Workbook

Sheet Common sized -Income Statement 
A1: Niket Shah
A2: COMMON SIZED INCOME STATEMENT - WALMART
A4: (Amounts in millions, except per share data) | B4: As of January 31
A5: Particulars | B5: 2024 | C5: Common Sized for 2024 | D5: 2023 | E5: Common Sized for 2023 | F5: 2022 | G5: Common Sized for 2022
A6: Revenues:
A7: Net sales | B7: 642637 | C7: =B7/$B$9 -> 0.9915325 | D7: 605881 | E7: =D7/$D$9 -> 0.99115312 | F7: 567762 | G7: =F7/$F$9 -> 0.99128422
A8: Membership and other income | B8: 5488 | C8: =B8/$B$9 -> 0.0084675024 | D8: 5408 | E8: =D8/$D$9 -> 0.0088468793 | F8: 4992 | G8: =F8/$F$9 -> 0.0087157837
A9: Total revenues | B9: =SUM(B7:B8) -> 648125 | C9: =B9/$B$9 -> 1 | D9: =SUM(D7:D8) -> 611289 | E9: =D9/$D$9 -> 1 | F9: =SUM(F7:F8) -> 572754 | G9: =F9/$F$9 -> 1
A10: Costs and expenses: | G10: =F10/$F$9 -> 0
A11: Cost of sales | B11: 490142 | C11: =B11/$B$9 -> 0.75624609 | D11: 463721 | E11: =D11/$D$9 -> 0.75859536 | F11: 429000 | G11: =F11/$F$9 -> 0.74901267
A12: Operating, selling, general and administrative expenses | B12: 130971 | C12: =B12/$B$9 -> 0.20207676 | D12: 127140 | E12: =D12/$D$9 -> 0.20798673 | F12: 117812 | G12: =F12/$F$9 -> 0.20569389
A13: Operating income | B13: =B9-B11-B12 -> 27012 | C13: =B13/$B$9 -> 0.041677146 | D13: =D9-D11-D12 -> 20428 | E13: =D13/$D$9 -> 0.033417909 | F13: =F9-F11-F12 -> 25942 | G13: =F13/$F$9 -> 0.045293442
A14: Interest: | G14: =F14/$F$9 -> 0
A15: Debt | B15: 2259 | C15: =B15/$B$9 -> 0.0034854388 | D15: 1787 | E15: =D15/$D$9 -> 0.0029233309 | F15: 1674 | G15: =F15/$F$9 -> 0.0029227207
A16: Finance lease | B16: 424 | C16: =B16/$B$9 -> 0.00065419479 | D16: 341 | E16: =D16/$D$9 -> 0.00055783762 | F16: 320 | G16: =F16/$F$9 -> 0.00055870409
A17: Interest income | B17: -546 | C17: =B17/$B$9 -> -0.00084243009 | D17: -254 | E17: =D17/$D$9 -> -0.00041551541 | F17: -158 | G17: =F17/$F$9 -> -0.00027586014
A18: Interest, net | B18: =SUM(B15:B17) -> 2137 | C18: =B18/$B$9 -> 0.0032972035 | D18: =SUM(D15:D17) -> 1874 | E18: =D18/$D$9 -> 0.0030656531 | F18: =SUM(F15:F17) -> 1836 | G18: =F18/$F$9 -> 0.0032055647
A19: Loss on extinguishment of debt | B19: — | D19: — | F19: 2410 | G19: =F19/$F$9 -> 0.0042077401
A20: Other (gains) and losses | B20: 3027 | C20: =B20/$B$9 -> 0.0046703954 | D20: 1538 | E20: =D20/$D$9 -> 0.0025159949 | F20: 3000 | G20: =F20/$F$9 -> 0.0052378508
A21: Income before income taxes | B21: =B13-B18-B20 -> 21848 | C21: =B21/$B$9 -> 0.033709547 | D21: =D13-D18-D20 -> 17016 | E21: =D21/$D$9 -> 0.027836261 | F21: =F13-F18-F19-F20 -> 18696 | G21: =F21/$F$9 -> 0.032642286
A22: Provision for income taxes | B22: 5578 | C22: =B22/$B$9 -> 0.0086063645 | D22: 5724 | E22: =D22/$D$9 -> 0.0093638197 | F22: 4756 | G22: =F22/$F$9 -> 0.0083037395
A23: Consolidated net income | B23: =B21-B22 -> 16270 | C23: =B23/$B$9 -> 0.025103182 | D23: =D21-D22 -> 11292 | E23: =D23/$D$9 -> 0.018472441 | F23: =F21-F22 -> 13940 | G23: =F23/$F$9 -> 0.024338547
A24: Consolidated net (income) loss attributable to noncontrolling interest | B24: -759 | C24: =B24/$B$9 -> -0.0011710704 | D24: 388 | E24: =D24/$D$9 -> 0.00063472433 | F24: -267 | G24: =F24/$F$9 -> -0.00046616872
A25: Consolidated net income attributable to Walmart | B25: =SUM(B23:B24) -> 15511 | C25: =B25/$B$9 -> 0.023932112 | D25: =SUM(D23:D24) -> 11680 | E25: =D25/$D$9 -> 0.019107165 | F25: =SUM(F23:F24) -> 13673 | G25: =F25/$F$9 -> 0.023872378
A27: Net income per common share:
A28: Basic net income per common share attributable to Walmart | B28: 1.92 | D28: 1.43 | F28: 1.63
A29: Diluted net income per common share attributable to Walmart | B29: 1.91 | D29: 1.42 | F29: 1.62
A31: Weighted-average common shares outstanding:
A32: Basic | B32: 8077 | D32: 8171 | F32: 8376
A33: Diluted | B33: 8108 | D33: 8202 | F33: 8415
A35: Dividends declared per common share | B35: 0.76 | D35: 0.7467 | F35: 0.7333

Sheet Sheet1
A3: (Amounts in millions, except per share data) | B3: Fiscal year Ended January 31,
A4: Particulars | B4: 2024 | C4: 2023 | D4: 2022
A5: Revenues:
A6: Net sales | B6: 642637 | C6: 605881 | D6: 567762
A7: Membership and other income | B7: 5488 | C7: 5408 | D7: 4992
A8: Total revenues | B8: =SUM(B6:B7) -> 648125 | C8: =SUM(C6:C7) -> 611289 | D8: =SUM(D6:D7) -> 572754
A9: Costs and expenses:
A10: Cost of sales | B10: 490142 | C10: 463721 | D10: 429000
A11: Operating, selling, general and administrative expenses | B11: 130971 | C11: 127140 | D11: 117812
A12: Operating income | B12: =B8-B10-B11 -> 27012 | C12: =C8-C10-C11 -> 20428 | D12: =D8-D10-D11 -> 25942
A13: Interest:
A14: Debt | B14: 2259 | C14: 1787 | D14: 1674
A15: Finance lease | B15: 424 | C15: 341 | D15: 320
A16: Interest income | B16: -546 | C16: -254 | D16: -158
A17: Interest, net | B17: =SUM(B14:B16) -> 2137 | C17: =SUM(C14:C16) -> 1874 | D17: =SUM(D14:D16) -> 1836
A18: Loss on extinguishment of debt | B18: 0 | C18: 0 | D18: 2410
A19: Other (gains) and losses | B19: 3027 | C19: 1538 | D19: 3000
A20: Income before income taxes | B20: =B12-B17-B19 -> 21848 | C20: =C12-C17-C19 -> 17016 | D20: =D12-D17-D19-D18 -> 18696
A21: Provision for income taxes | B21: 5578 | C21: 5724 | D21: 4756
A22: Consolidated net income | B22: =B20-B21 -> 16270 | C22: =C20-C21 -> 11292 | D22: =D20-D21 -> 13940
A23: Consolidated net (income) loss attributable to noncontrolling interest | B23: -759 | C23: 388 | D23: -267
A24: Consolidated net income attributable to Walmart | B24: =SUM(B22:B23) -> 15511 | C24: =SUM(C22:C23) -> 11680 | D24: =SUM(D22:D23) -> 13673
A26: Net income per common share:
A27: Basic net income per common share attributable to Walmart | B27: 1.92 | C27: 1.43 | D27: 1.63
A28: Diluted net income per common share attributable to Walmart | B28: 1.91 | C28: 1.42 | D28: 1.62
A30: Weighted-average common shares outstanding:
A31: Basic | B31: 8077 | C31: 8171 | D31: 8376
A32: Diluted | B32: 8108 | C32: 8202 | D32: 8415
A34: Dividends declared per common share | B34: 0.76 | C34: 0.7467 | D34: 0.7333

Sheet Sheet2
A3: (Amt in Miliions) | B3: As of January 31
A4: Particulars | B4: 2024 | C4: 2023
A5: ASSETS
A6: Current assets:
A7: Cash and cash equivalents | B7: 9867 | C7: 8625
A8: Receivables, net | B8: 8796 | C8: 7933
A9: Inventories | B9: 54892 | C9: 56576
A10: Prepaid expenses and other | B10: 3322 | C10: 2521
A11: Total current assets | B11: =SUM(B7:B10) -> 76877 | C11: =SUM(C7:C10) -> 75655
A13: Property and equipment, net | B13: 110810 | C13: 100760
A14: Operating lease right-of-use assets | B14: 13673 | C14: 13555
A15: Finance lease right-of-use assets, net | B15: 5855 | C15: 4919
A16: Goodwill | B16: 28113 | C16: 28174
A17: Other long-term assets | B17: 17071 | C17: 20134
A18: Total assets | B18: =SUM(B11:B17) -> 252399 | C18: =SUM(C11:C17) -> 243197
A19: LIABILITIES, REDEEMABLE NONCONTROLLING INTEREST, AND EQUITY
A20: Current liabilities:
A21: Short-term borrowings | B21: 878 | C21: 372
A22: Accounts payable | B22: 56812 | C22: 53742
A23: Accrued liabilities | B23: 28759 | C23: 31126
A24: Accrued income taxes | B24: 307 | C24: 727
A25: Long-term debt due within one year | B25: 3447 | C25: 4191
A26: Operating lease obligations due within one year | B26: 1487 | C26: 1473
A27: Finance lease obligations due within one year | B27: 725 | C27: 567
A28: Total current liabilities | B28: =SUM(B21:B27) -> 92415 | C28: =SUM(C21:C27) -> 92198
A30: Long-term debt | B30: 36132 | C30: 34649
A31: Long-term operating lease obligations | B31: 12943 | C31: 12828
A32: Long-term finance lease obligations | B32: 5709 | C32: 4843
A33: Deferred income taxes and other | B33: 14629 | C33: 14688
A35: Commitments and contingencies
A37: Redeemable noncontrolling interest | B37: 222 | C37: 237
A39: Equity:
A40: Common stock | B40: 805 | C40: 808
A41: Capital in excess of par value | B41: 4544 | C41: 4430
A42: Retained earnings | B42: 89814 | C42: 83135
A43: Accumulated other comprehensive loss | B43: -11302 | C43: -11680
A44: Total Walmart shareholders' equity | B44: =SUM(B40:B43) -> 83861 | C44: =SUM(C40:C43) -> 76693
A45: Noncontrolling interest | B45: 6488 | C45: 7061
A46: Total equity | B46: =SUM(B44:B45) -> 90349 | C46: =SUM(C44:C45) -> 83754
A47: Total liabilities, redeemable noncontrolling interest, and equity | B47: =B28+B30+B31+B32+B33+B37+B46 -> 252399 | C47: =C28+C30+C31+C32+C33+C37+C46 -> 243197

Sheet Common Sized-Balance Sheet 
A1: Niket Shah
A2: COMMON SIZED BALANCE SHEET - WALMART
A4: (Amt in Miliions) | B4: As of January 31
A5: Particulars | B5: 2024 | C5: Change in % | D5: 2023 | E5: Change in %
A6: ASSETS
A7: Current assets:
A8: Cash and cash equivalents | B8: 9867 | C8: =B8/$B$19 -> 0.039092865 | D8: 8625 | E8: =D8/$D$19 -> 0.035465076
A9: Receivables, net | B9: 8796 | C9: =B9/$B$19 -> 0.034849583 | D9: 7933 | E9: =D9/$D$19 -> 0.032619646
A10: Inventories | B10: 54892 | C10: =B10/$B$19 -> 0.21748105 | D10: 56576 | E10: =D10/$D$19 -> 0.23263445
A11: Prepaid expenses and other | B11: 3322 | C11: =B11/$B$19 -> 0.0131617 | D11: 2521 | E11: =D11/$D$19 -> 0.010366082
A12: Total current assets | B12: =SUM(B8:B11) -> 76877 | C12: =B12/$B$19 -> 0.3045852 | D12: =SUM(D8:D11) -> 75655 | E12: =D12/$D$19 -> 0.31108525
A14: Property and equipment, net | B14: 110810 | C14: =B14/$B$19 -> 0.4390271 | D14: 100760 | E14: =D14/$D$19 -> 0.41431432
A15: Operating lease right-of-use assets | B15: 13673 | C15: =B15/$B$19 -> 0.054172164 | D15: 13555 | E15: =D15/$D$19 -> 0.055736707
A16: Finance lease right-of-use assets, net | B16: 5855 | C16: =B16/$B$19 -> 0.023197398 | D16: 4919 | E16: =D16/$D$19 -> 0.020226401
A17: Goodwill | B17: 28113 | C17: =B17/$B$19 -> 0.11138317 | D17: 28174 | E17: =D17/$D$19 -> 0.11584847
A18: Other long-term assets | B18: 17071 | C18: =B18/$B$19 -> 0.067634975 | D18: 20134 | E18: =D18/$D$19 -> 0.08278885
A19: Total assets | B19: =SUM(B12:B18) -> 252399 | C19: =B19/$B$19 -> 1 | D19: =SUM(D12:D18) -> 243197 | E19: =D19/$D$19 -> 1
A20: LIABILITIES, REDEEMABLE NONCONTROLLING INTEREST, AND EQUITY
A21: Current liabilities:
A22: Short-term borrowings | B22: 878 | C22: =B22/$B$19 -> 0.0034786192 | D22: 372 | E22: =D22/$D$19 -> 0.0015296241
A23: Accounts payable | B23: 56812 | C23: =B23/$B$19 -> 0.22508806 | D23: 53742 | E23: =D23/$D$19 -> 0.22098134
A24: Accrued liabilities | B24: 28759 | C24: =B24/$B$19 -> 0.11394261 | D24: 31126 | E24: =D24/$D$19 -> 0.12798678
A25: Accrued income taxes | B25: 307 | C25: =B25/$B$19 -> 0.0012163281 | D25: 727 | E25: =D25/$D$19 -> 0.0029893461
A26: Long-term debt due within one year | B26: 3447 | C26: =B26/$B$19 -> 0.013656948 | D26: 4191 | E26: =D26/$D$19 -> 0.017232943
A27: Operating lease obligations due within one year | B27: 1487 | C27: =B27/$B$19 -> 0.0058914655 | D27: 1473 | E27: =D27/$D$19 -> 0.0060568181
A28: Finance lease obligations due within one year | B28: 725 | C28: =B28/$B$19 -> 0.0028724361 | D28: 567 | E28: =D28/$D$19 -> 0.0023314432
A29: Total current liabilities | B29: =SUM(B22:B28) -> 92415 | C29: =B29/$B$19 -> 0.36614646 | D29: =SUM(D22:D28) -> 92198 | E29: =D29/$D$19 -> 0.37910829
A31: Long-term debt | B31: 36132 | C31: =B31/$B$19 -> 0.14315429 | D31: 34649 | E31: =D31/$D$19 -> 0.14247297
A32: Long-term operating lease obligations | B32: 12943 | C32: =B32/$B$19 -> 0.051279918 | D32: 12828 | E32: =D32/$D$19 -> 0.052747361
A33: Long-term finance lease obligations | B33: 5709 | C33: =B33/$B$19 -> 0.022618949 | D33: 4843 | E33: =D33/$D$19 -> 0.019913897
A34: Deferred income taxes and other | B34: 14629 | C34: =B34/$B$19 -> 0.057959818 | D34: 14688 | E34: =D34/$D$19 -> 0.060395482
A36: Commitments and contingencies
A38: Redeemable noncontrolling interest | B38: 222 | C38: =B38/$B$19 -> 0.00087955974 | D38: 237 | E38: =D38/$D$19 -> 0.0009745186
A40: Equity:
A41: Common stock | B41: 805 | C41: =B41/$B$19 -> 0.0031893946 | D41: 808 | E41: =D41/$D$19 -> 0.0033224094
A42: Capital in excess of par value | B42: 4544 | C42: =B42/$B$19 -> 0.018003241 | D42: 4430 | E42: =D42/$D$19 -> 0.018215685
A43: Retained earnings | B43: 89814 | C43: =B43/$B$19 -> 0.35584135 | D43: 83135 | E43: =D43/$D$19 -> 0.34184221
A44: Accumulated other comprehensive loss | B44: -11302 | C44: =B44/$B$19 -> -0.044778307 | D44: -11680 | E44: =D44/$D$19 -> -0.048026908
A45: Total Walmart shareholders' equity | B45: =SUM(B41:B44) -> 83861 | C45: =B45/$B$19 -> 0.33225567 | D45: =SUM(D41:D44) -> 76693 | E45: =D45/$D$19 -> 0.3153534
A46: Noncontrolling interest | B46: 6488 | C46: =B46/$B$19 -> 0.025705332 | D46: 7061 | E46: =D46/$D$19 -> 0.029034075
...

Sheet Fluctuation- Income Statement
A1: Niket Shah
A2: FLUCTUATION ANALYSIS INCOME STATEMENT - WALMART
A5: (Amounts in millions, except per share data) | B5: As of January 31,
E6: For Year 2024 | G6: For Year 2023
A7: Particulars | B7: 2024 | C7: 2023 | D7: 2022 | E7: Change in $ | F7: Change in % | G7: Change in $ | H7: Change in %
A8: Revenues:
A9: Net sales | B9: 642637 | C9: 605881 | D9: 567762 | E9: =B9-C9 -> 36756 | F9: =E9/C9 -> 0.060665378 | G9: =C9-D9 -> 38119 | H9: =G9/D9 -> 0.067139048
A10: Membership and other income | B10: 5488 | C10: 5408 | D10: 4992 | E10: =B10-C10 -> 80 | F10: =E10/C10 -> 0.014792899 | G10: =C10-D10 -> 416 | H10: =G10/D10 -> 0.083333333
A11: Total revenues | B11: =SUM(B9:B10) -> 648125 | C11: =SUM(C9:C10) -> 611289 | D11: =SUM(D9:D10) -> 572754 | E11: =B11-C11 -> 36836 | F11: =E11/C11 -> 0.06025955 | G11: =C11-D11 -> 38535 | H11: =G11/D11 -> 0.067280194
A12: Costs and expenses:
A13: Cost of sales | B13: 490142 | C13: 463721 | D13: 429000 | E13: =B13-C13 -> 26421 | F13: =E13/C13 -> 0.05697607 | G13: =C13-D13 -> 34721 | H13: =G13/D13 -> 0.080934732
A14: Operating, selling, general and administrative expenses | B14: 130971 | C14: 127140 | D14: 117812 | E14: =B14-C14 -> 3831 | F14: =E14/C14 -> 0.030132138 | G14: =C14-D14 -> 9328 | H14: =G14/D14 -> 0.079176994
A15: Operating income | B15: =B11-B13-B14 -> 27012 | C15: =C11-C13-C14 -> 20428 | D15: =D11-D13-D14 -> 25942 | E15: =B15-C15 -> 6584 | F15: =E15/C15 -> 0.32230272 | G15: =C15-D15 -> -5514 | H15: =G15/D15 -> -0.21255108
A16: Interest:
A17: Debt | B17: 2259 | C17: 1787 | D17: 1674 | E17: =B17-C17 -> 472 | F17: =E17/C17 -> 0.26412983 | G17: =C17-D17 -> 113 | H17: =G17/D17 -> 0.067502987
A18: Finance lease | B18: 424 | C18: 341 | D18: 320 | E18: =B18-C18 -> 83 | F18: =E18/C18 -> 0.24340176 | G18: =C18-D18 -> 21 | H18: =G18/D18 -> 0.065625
A19: Interest income | B19: -546 | C19: -254 | D19: -158 | E19: =B19-C19 -> -292 | F19: =E19/C19 -> 1.1496063 | G19: =C19-D19 -> -96 | H19: =G19/D19 -> 0.60759494
A20: Interest, net | B20: =SUM(B17:B19) -> 2137 | C20: =SUM(C17:C19) -> 1874 | D20: =SUM(D17:D19) -> 1836 | E20: =B20-C20 -> 263 | F20: =E20/C20 -> 0.14034152 | G20: =C20-D20 -> 38 | H20: =G20/D20 -> 0.020697168
A21: Loss on extinguishment of debt | B21: 0 | C21: 0 | D21: 2410 | E21: =B21-C21 -> 0 | G21: =C21-D21 -> -2410 | H21: =G21/D21 -> -1
A22: Other (gains) and losses | B22: 3027 | C22: 1538 | D22: 3000 | E22: =B22-C22 -> 1489 | F22: =E22/C22 -> 0.96814044 | G22: =C22-D22 -> -1462 | H22: =G22/D22 -> -0.48733333
A23: Income before income taxes | B23: =B15-B20-B22 -> 21848 | C23: =C15-C20-C22 -> 17016 | D23: =D15-D20-D22-D21 -> 18696 | E23: =B23-C23 -> 4832 | F23: =E23/C23 -> 0.28396803 | G23: =C23-D23 -> -1680 | H23: =G23/D23 -> -0.089858793
A24: Provision for income taxes | B24: 5578 | C24: 5724 | D24: 4756 | E24: =B24-C24 -> -146 | F24: =E24/C24 -> -0.025506639 | G24: =C24-D24 -> 968 | H24: =G24/D24 -> 0.20353238
A25: Consolidated net income | B25: =B23-B24 -> 16270 | C25: =C23-C24 -> 11292 | D25: =D23-D24 -> 13940 | E25: =B25-C25 -> 4978 | F25: =E25/C25 -> 0.44084307 | G25: =C25-D25 -> -2648 | H25: =G25/D25 -> -0.18995696
A26: Consolidated net (income) loss attributable to noncontrolling interest | B26: -759 | C26: 388 | D26: -267 | E26: =B26-C26 -> -1147 | F26: =E26/C26 -> -2.9561856 | G26: =C26-D26 -> 655 | H26: =G26/D26 -> -2.4531835
A27: Consolidated net income attributable to Walmart | B27: =SUM(B25:B26) -> 15511 | C27: =SUM(C25:C26) -> 11680 | D27: =SUM(D25:D26) -> 13673 | E27: =B27-C27 -> 3831 | F27: =E27/C27 -> 0.32799658 | G27: =C27-D27 -> -1993 | H27: =G27/D27 -> -0.14576172
A29: Net income per common share:
A30: Basic net income per common share attributable to Walmart | B30: 1.92 | C30: 1.43 | D30: 1.63
A31: Diluted net income per common share attributable to Walmart | B31: 1.91 | C31: 1.42 | D31: 1.62
A33: Weighted-average common shares outstanding:
A34: Basic | B34: 8077 | C34: 8171 | D34: 8376
A35: Diluted | B35: 8108 | C35: 8202 | D35: 8415
A37: Dividends declared per common share | B37: 0.76 | C37: 0.7467 | D37: 0.7333

Sheet Fluctuation- Balance Sheet 
A1: Niket Shah
A2: FLUCTUATION ANALYSIS INCOME STATEMENT - WALMART
A3: (Amt in Miliions) | B3: As of January 31
A4: Particulars | B4: 2024 | C4: 2023 | D4: CHANGE IN $ | E4: CHANGE IN %
A5: ASSETS
A6: Current assets:
A7: Cash and cash equivalents | B7: 9867 | C7: 8625 | D7: =B7-C7 -> 1242 | E7: =D7/C7 -> 0.144
A8: Receivables, net | B8: 8796 | C8: 7933 | D8: =B8-C8 -> 863 | E8: =D8/C8 -> 0.10878608
A9: Inventories | B9: 54892 | C9: 56576 | D9: =B9-C9 -> -1684 | E9: =D9/C9 -> -0.029765271
A10: Prepaid expenses and other | B10: 3322 | C10: 2521 | D10: =B10-C10 -> 801 | E10: =D10/C10 -> 0.31773106
A11: Total current assets | B11: =SUM(B7:B10) -> 76877 | C11: =SUM(C7:C10) -> 75655 | D11: =B11-C11 -> 1222 | E11: =D11/C11 -> 0.01615227
A13: Property and equipment, net | B13: 110810 | C13: 100760 | D13: =B13-C13 -> 10050 | E13: =D13/C13 -> 0.099741961
A14: Operating lease right-of-use assets | B14: 13673 | C14: 13555 | D14: =B14-C14 -> 118 | E14: =D14/C14 -> 0.0087052748
A15: Finance lease right-of-use assets, net | B15: 5855 | C15: 4919 | D15: =B15-C15 -> 936 | E15: =D15/C15 -> 0.19028258
A16: Goodwill | B16: 28113 | C16: 28174 | D16: =B16-C16 -> -61 | E16: =D16/C16 -> -0.0021651168
A17: Other long-term assets | B17: 17071 | C17: 20134 | D17: =B17-C17 -> -3063 | E17: =D17/C17 -> -0.15213072
A18: Total assets | B18: =SUM(B11:B17) -> 252399 | C18: =SUM(C11:C17) -> 243197 | D18: =B18-C18 -> 9202 | E18: =D18/C18 -> 0.037837638
A19: LIABILITIES, REDEEMABLE NONCONTROLLING INTEREST, AND EQUITY
A20: Current liabilities:
A21: Short-term borrowings | B21: 878 | C21: 372 | D21: =B21-C21 -> 506 | E21: =D21/C21 -> 1.3602151
A22: Accounts payable | B22: 56812 | C22: 53742 | D22: =B22-C22 -> 3070 | E22: =D22/C22 -> 0.057124781
A23: Accrued liabilities | B23: 28759 | C23: 31126 | D23: =B23-C23 -> -2367 | E23: =D23/C23 -> -0.07604575
A24: Accrued income taxes | B24: 307 | C24: 727 | D24: =B24-C24 -> -420 | E24: =D24/C24 -> -0.57771664
A25: Long-term debt due within one year | B25: 3447 | C25: 4191 | D25: =B25-C25 -> -744 | E25: =D25/C25 -> -0.17752326
A26: Operating lease obligations due within one year | B26: 1487 | C26: 1473 | D26: =B26-C26 -> 14 | E26: =D26/C26 -> 0.0095044128
A27: Finance lease obligations due within one year | B27: 725 | C27: 567 | D27: =B27-C27 -> 158 | E27: =D27/C27 -> 0.27865961
A28: Total current liabilities | B28: =SUM(B21:B27) -> 92415 | C28: =SUM(C21:C27) -> 92198 | D28: =B28-C28 -> 217 | E28: =D28/C28 -> 0.0023536302
A30: Long-term debt | B30: 36132 | C30: 34649 | D30: =B30-C30 -> 1483 | E30: =D30/C30 -> 0.042800658
A31: Long-term operating lease obligations | B31: 12943 | C31: 12828 | D31: =B31-C31 -> 115 | E31: =D31/C31 -> 0.0089647646
A32: Long-term finance lease obligations | B32: 5709 | C32: 4843 | D32: =B32-C32 -> 866 | E32: =D32/C32 -> 0.17881478
A33: Deferred income taxes and other | B33: 14629 | C33: 14688 | D33: =B33-C33 -> -59 | E33: =D33/C33 -> -0.0040168845
A35: Commitments and contingencies
A37: Redeemable noncontrolling interest | B37: 222 | C37: 237 | D37: =B37-C37 -> -15
A39: Equity:
A40: Common stock | B40: 805 | C40: 808 | D40: =B40-C40 -> -3 | E40: =D40/C40 -> -0.0037128713
A41: Capital in excess of par value | B41: 4544 | C41: 4430 | D41: =B41-C41 -> 114 | E41: =D41/C41 -> 0.025733634
A42: Retained earnings | B42: 89814 | C42: 83135 | D42: =B42-C42 -> 6679 | E42: =D42/C42 -> 0.080339207
A43: Accumulated other comprehensive loss | B43: -11302 | C43: -11680 | D43: =B43-C43 -> 378 | E43: =D43/C43 -> -0.032363014
A44: Total Walmart shareholders' equity | B44: =SUM(B40:B43) -> 83861 | C44: =SUM(C40:C43) -> 76693 | D44: =B44-C44 -> 7168 | E44: =D44/C44 -> 0.093463549
A45: Noncontrolling interest | B45: 6488 | C45: 7061 | D45: =B45-C45 -> -573 | E45: =D45/C45 -> -0.081149979
...

Sheet Ratio Analysis 
A1: Niket Shah
A2: RATIO ANALYSIS - WALMART
C4: As of January 31,
A5: Ratios | B5: Formula | C5: Calculation | D5: 2024 | E5: Calculation | F5: 2023
A7: Solvency Ratio
A9: Debt to Equity ratio | B9: Total Debt/Shareholders’ Equity | C9: 92,415 + 36,132 + 12,943 + 5,709 = 147,199 | D9: =147199/'Common Sized-Balance Sheet '!B47 -> 1.6292267 | E9: 92,198 + 34,649 + 12,828 + 4,843 = 134,494 | F9: =134494/'Common Sized-Balance Sheet '!D47 -> 1.6058218
A10: Debt Ratio | B10: Total Debt(Short Term Borrowings + Long Term Debt + Current Maturities) / Total Assets | C10: 878+3447+36132 = 40457 | D10: =40457/'Common Sized-Balance Sheet '!B19 -> 0.16028986 | E10: 372+4191+34649 = 39212 | F10: =39212/'Common Sized-Balance Sheet '!D19 -> 0.16123554
A11: Equity ratio | B11: Shareholders’ Equity/Total Assets | D11: ='Common Sized-Balance Sheet '!B47/'Common Sized-Balance Sheet '!B19 -> 0.35796101 | F11: ='Common Sized-Balance Sheet '!D47/'Common Sized-Balance Sheet '!D19 -> 0.34438747
A12: Debt to asset ratio | B12: Total Debt/Total Asset | D12: =147199/'Common Sized-Balance Sheet '!B19 -> 0.58319962 | F12: =134494/'Common Sized-Balance Sheet '!D19 -> 0.55302491
A13: Interest Coverage Ratio | B13: EBIT / Interest Expense | D13: =('Common sized -Income Statement '!B13+'Common sized -Income Statement '!B18)/'Common sized -Income Statement '!B18 -> 13.64015 | F13: =('Common sized -Income Statement '!D13+'Common sized -Income Statement '!D18)/'Common sized -Income Statement '!D18 -> 11.900747
A15: Liquidity Ratios
A17: Cash Ratio | B17: Cash & Cah Equivalents / Current Liabilities | D17: ='Common Sized-Balance Sheet '!B8/'Common Sized-Balance Sheet '!B29 -> 0.10676838 | F17: ='Common Sized-Balance Sheet '!D8/'Common Sized-Balance Sheet '!D29 -> 0.093548667
A18: Quick Ratio | B18: Current Assets - Inventory / Current Liabilties | D18: =('Common Sized-Balance Sheet '!B12-'Common Sized-Balance Sheet '!B10)/'Common Sized-Balance Sheet '!B29 -> 0.23789428 | F18: =('Common Sized-Balance Sheet '!D12-'Common Sized-Balance Sheet '!D10)/'Common Sized-Balance Sheet '!D29 -> 0.20693507
A19: Current Ratio | B19: Current Assets / Current Liabilties | D19: ='Common Sized-Balance Sheet '!B12/'Common Sized-Balance Sheet '!B29 -> 0.83186712 | F19: ='Common Sized-Balance Sheet '!D12/'Common Sized-Balance Sheet '!D29 -> 0.82057095
A22: Profitabilty Ratios
A24: Gross Profit Ratio | B24: Gross Profit / Net Sales | D24: =('Common sized -Income Statement '!B7-'Common sized -Income Statement '!B11)/'Common sized -Income Statement '!B7 -> 0.23729571 | F24: =('Common sized -Income Statement '!D7-'Common sized -Income Statement '!D11)/'Common sized -Income Statement '!D7 -> 0.23463353
A25: Net Profit Ratio | B25: Net Profit / Net Sales | D25: ='Common sized -Income Statement '!B25/'Common sized -Income Statement '!B9 -> 0.023932112 | F25: ='Common sized -Income Statement '!D25/'Common sized -Income Statement '!D9 -> 0.019107165
A26: Return on Assets | B26: Net Income / Average Total Assets | C26: (252,399 + 243,197) / 2 = 247798 | D26: =15511/247798 -> 0.06259534 | E26: (243,197 + 234,526) / 2 = 238861.5 | F26: =11680/238861.5 -> 0.04889863
A27: Return on Equity | B27: Net Income / Average Shareholders Equity | C27: (83,861 + 76,693) / 2 = 80277 | D27: =15511/80277 -> 0.19321848 | E27: (76,693 + 71,130) / 2 = 73911.5 | F27: =11680/73911.5 -> 0.15802683
A28: Operating Profit Ratio | B28: Operating Income/ Net Sales | D28: ='Common sized -Income Statement '!B13/'Common sized -Income Statement '!B7 -> 0.042033061 | F28: ='Common sized -Income Statement '!D13/'Common sized -Income Statement '!D7 -> 0.033716192
A30: Activity Ratios
A31: Asset Turnover Ratio: | B31: Total Revenues​/ Average Total Assets | C31: (252,399 + 243,197) / 2 = 247798 | D31: ='Common sized -Income Statement '!B9/247798 -> 2.6155377 | E31: (243,197 + 234,526) / 2 = 238861.5 | F31: ='Common sized -Income Statement '!D9/238861.5 -> 2.5591776
A32: Receivables Turnover Ratio: | B32: Net Sales / Average Receivables | C32: (8,796 + 7,933) / 2 = 8365 | D32: ='Common sized -Income Statement '!B7/8365 -> 76.824507 | E32: (7,933 + 7,543) / 2 = 7738 | F32: ='Common sized -Income Statement '!D7/7738 -> 78.299431
A33: Inventory Turnover Ratio: | B33: Cost of Sales​/ Average Inventory | C33: (54,892 + 56,576) / 2 = 55734 | D33: ='Common sized -Income Statement '!B11/55734 -> 8.7943087 | E33: (56,576 + 55,160) / 2 = 55868 | F33: ='Common sized -Income Statement '!D11/55868 -> 8.3002971
A34: Days Inventory Outstanding: | B34: 365/ Inventory Turnover Ratio | C34: 365/8.79 = 41.52 | D34: 41.52 days | E34: 365/8.3 = 43.98 | F34: 43.98 days

Sheet SWOT Analysis
A1: Niket Shah
B2: WALMART - SWOT ANALYSIS
A4: STRENGTHS
A5: Good Reputation: | B5: One of the largest retailers in the world, Walmart has a strong reputation as a brand. It has significant advantages over competitors, including economies of scale.
A7: Revenue and Profit Growth: | B7: Walmart's revenue showed a robust growth trajectory, rising from $567.76 billion in FY2022 to $642.64 billion in FY2024.
B8: From FY2022 to FY2024, net income increased 17% from $13.94 billion to $16.27 billion, indicating strong profitability.
A10: Strong Cash Flow: | B10: Walmart's significant operating cash flow ($35.73 billion in FY2024) allows it to finance expenses, distribute dividends, and buy back stock.
A12: Several Revenue Sources: | B12: Membership fees, net sales, and other sources are some of the ways that Walmart generates revenue.
B13: Because of this diversification, the corporation is less dependent on any one aspect of its operations.
A15: Global Presence and Supply network: | B15: Walmart is able to maintain low costs and pass savings on to customers because to its vast and efficient supply network.
B16: It is also developing its digital and e-commerce talents to effectively engage in the online retail sector.
A18: WEAKNESSESS
A20: Minimal Profit Margin: | B20: Walmart's emphasis on low prices and high sales volume means that, like many large retailers, it works on small profit margins.
B21: This leaves the business open to increases in labor, supply chain, and other operational costs.
A23: Growing Interest and Operating Costs: | B23: Operating costs have risen gradually, rising from $117.81 billion in FY2022 to $130.97 billion in FY2024. Additionally, because of the company's debt,
B24: interest expenses increased from $1.83 billion in FY2022 to $2.14 billion in FY2024.
A26: Dependency on the US market: | B26: Despite its global reach, Walmart still gets a significant portion of its revenue from the US market.
B27: As a result, the company is vulnerable to shifts in domestic economic conditions, consumer purchasing trends, and legislation.
A29: Labor and supply chain costs: | B29: Walmart's profitability may be impacted if growing labor expenses and supply chain disruption issues, such as transportation issues or inflationary pressures, are not adequately managed.
A31: OPPORTUNITIES
A33: E-business and Digital Growth: | B33: Walmart has made significant strides in its digital capabilities and e-commerce operations, which present opportunities to grow its share of the online retail sector.
B34: The business is investing in online platforms and logistics, which is creating new development potential.
A36: Development in Developing Markets and Globalization: | B36: Walmart may expand its presence in uncharted territories, particularly in developing countries, despite being a significant participant on a global level.
A38: Technological Advancements: | B38: Through the use of technologies like automation, data analytics, and artificial intelligence (AI), Walmart can increase customer satisfaction, optimize operations, and make better decisions.
A40: Green initiatives and sustainability: | B40: As consumer interest in sustainability increases, Walmart has an opportunity to strengthen its brand by promoting eco-friendly products, reducing waste, and enhancing eco-friendly procedures.
A42: THREATS
A44: Tough Competition: | B44: Walmart is up against fierce competition from e-commerce behemoths like Amazon, specialty shops, and other big-box stores like Target and Costco.
B45: Walmart is under pressure from this competition to stick to its low-price approach, which may have an effect on profitability.
A47: Economic downturns: | B47: Economic factors, such as recessions, inflation, and shifts in consumer purchasing, can have a big influence on the company's profitability. The demand for discretionary goods may decline during economic downturns.
A49: Chain disruptions: | B49: Global supply chain disruptions remain a risk, particularly in the aftermath of COVID-19 and other geopolitical events. The company may experience delays,
B50: product shortages, or cost hikes as a result of these disruptions for Walmart.
